<robot name="adam1_servo" version="1.0">
  <joint name="left_hip_roll_joint" type="revolute">
    <limit lower="-0.10000" upper="0.69000" effort="6.86000" velocity="7.48000"/>
    <origin rpy="0.00000 0.00000 0.00000" xyz="0.02870 0.02438 0.04900"/>
    <parent link="pelvis_link"/>
    <child link="left_hip_roll_link"/>
    <axis xyz="1.00000 0.00000 0.00000"/>
  </joint>
  <joint name="left_hip_yaw_joint" type="revolute">
    <limit lower="-0.76000" upper="0.76000" effort="6.86000" velocity="7.48000"/>
    <origin rpy="0.00000 0.00000 0.00000" xyz="-0.02158 0.05996 -0.00868"/>
    <parent link="left_hip_roll_link"/>
    <child link="left_hip_yaw_link"/>
    <axis xyz="0.00000 0.00000 1.00000"/>
  </joint>  
  <joint name="left_hip_pitch_joint" type="revolute">
    <limit lower="-1.57000" upper="1.57000" effort="6.86000" velocity="7.48000"/>
    <origin rpy="0.00000 0.00000 0.00000" xyz="-0.00462 0.02548 -0.02670"/>
    <parent link="left_hip_yaw_link"/>
    <child link="left_hip_pitch_link"/>
    <axis xyz="0.00000 1.00000 0.00000"/>
  </joint>
  <joint name="left_knee_joint" type="revolute">
    <limit lower="-1.57000" upper="0.00000" effort="6.86000" velocity="7.48000"/>
    <origin rpy="0.00000 0.00000 0.00000" xyz="-0.00000 -0.00943 -0.20200"/>
    <parent link="left_hip_pitch_link"/>
    <child link="left_knee_link"/>
    <axis xyz="0.00000 -1.00000 0.00000"/>
  </joint>
  <joint name="left_ankle_roll_joint" type="revolute">
    <limit lower="-0.26000" upper="0.26000" effort="1.67000" velocity="6.98000"/>
    <origin rpy="0.00000 0.00000 0.00000" xyz="0.01915 -0.01895 -0.16500"/>
    <parent link="left_knee_link"/>
    <child link="left_ankle_roll_link"/>
    <axis xyz="1.00000 0.00000 0.00000"/>
  </joint>
  <joint name="left_ankle_pitch_joint" type="revolute">
    <limit lower="-0.87000" upper="0.52000" effort="1.67000" velocity="6.98000"/>
    <origin rpy="0.00000 0.00000 0.00000" xyz="-0.01900 0.01895 -0.03500"/>
    <parent link="left_ankle_roll_link"/>
    <child link="left_ankle_pitch_link"/>
    <axis xyz="0.00000 1.00000 0.00000"/>
  </joint>
  <joint name="right_hip_roll_joint" type="revolute">
    <limit lower="-0.69000" upper="0.10000" effort="6.86000" velocity="7.48000"/>
    <origin rpy="0.00000 0.00000 0.00000" xyz="0.02870 -0.02482 0.04897"/>
    <parent link="pelvis_link"/>
    <child link="right_hip_roll_link"/>
    <axis xyz="1.00000 0.00000 0.00000"/>
  </joint>
  <joint name="right_hip_yaw_joint" type="revolute">
    <limit lower="-0.76000" upper="0.76000" effort="6.86000" velocity="7.48000"/>
    <origin rpy="0.00000 0.00000 0.00000" xyz="-0.02158 -0.05996 -0.00867"/>
    <parent link="right_hip_roll_link"/>
    <child link="right_hip_yaw_link"/>
    <axis xyz="0.00000 0.00000 1.00000"/>
  </joint>
  <joint name="right_hip_pitch_joint" type="revolute">
    <limit lower="-1.57000" upper="1.57000" effort="6.86000" velocity="7.48000"/>
    <origin rpy="0.00000 0.00000 0.00000" xyz="-0.00462 -0.02548 -0.02670"/>
    <parent link="right_hip_yaw_link"/>
    <child link="right_hip_pitch_link"/>
    <axis xyz="0.00000 1.00000 0.00000"/>
  </joint>
  <joint name="right_knee_joint" type="revolute">
    <limit lower="-1.97000" upper="0.00000" effort="6.86000" velocity="7.48000"/>
    <origin rpy="0.00000 0.00000 0.00000" xyz="-0.00000 0.00942 -0.20200"/>
    <parent link="right_hip_pitch_link"/>
    <child link="right_knee_link"/>
    <axis xyz="0.00000 -1.00000 0.00000"/>
  </joint>
  <joint name="right_ankle_roll_joint" type="revolute">
    <limit lower="-0.26000" upper="0.26000" effort="1.67000" velocity="6.98000"/>
    <origin rpy="0.00000 0.00000 0.00000" xyz="0.01915 0.01895 -0.16500"/>
    <parent link="right_knee_link"/>
    <child link="right_ankle_roll_link"/>
    <axis xyz="1.00000 0.00000 0.00000"/>
  </joint>
  <joint name="right_ankle_pitch_joint" type="revolute">
    <limit lower="-0.52000" upper="0.87000" effort="1.67000" velocity="6.98000"/>
    <origin rpy="0.00000 0.00000 0.00000" xyz="-0.01900 -0.01895 -0.03500"/>
    <parent link="right_ankle_roll_link"/>
    <child link="right_ankle_pitch_link"/>
    <axis xyz="0.00000 1.00000 0.00000"/>
  </joint>
  <joint name="torso_pitch_joint" type="fixed">
    <limit lower="-0.79000" upper="0.79000" effort="6.86000" velocity="7.48000"/>
    <origin rpy="0.00000 0.00000 0.00000" xyz="0.03300 0.02845 0.11614"/>
    <parent link="pelvis_link"/>
    <child link="torso_pitch_link"/>
    <axis xyz="0.00000 1.00000 0.00000"/>
  </joint>
  <joint name="torso_roll_joint" type="fixed">
    <limit lower="-0.79000" upper="0.79000" effort="6.86000" velocity="7.48000"/>
    <origin rpy="0.00000 0.00000 0.00000" xyz="-0.07470 -0.02870 0.02118"/>
    <parent link="torso_pitch_link"/>
    <child link="torso_roll_link"/>
    <axis xyz="1.00000 0.00000 0.00000"/>
  </joint>
  <joint name="torso_yaw_joint" type="fixed">
    <limit lower="-1.57000" upper="1.57000" effort="6.86000" velocity="7.48000"/>
    <origin rpy="0.00000 0.00000 0.00000" xyz="0.06004 0.00000 0.05978"/>
    <parent link="torso_roll_link"/>
    <child link="torso_yaw_link"/>
    <axis xyz="0.00000 0.00000 1.00000"/>
  </joint>
  <joint name="head_yaw_joint" type="fixed">
    <limit lower="-1.57000" upper="1.57000" effort="1.67000" velocity="6.98000"/>
    <origin rpy="0.00000 0.00000 0.00000" xyz="0.01869 -0.00005 0.16322"/>
    <parent link="torso_yaw_link"/>
    <child link="head_yaw_link"/>
    <axis xyz="0.00000 0.00000 1.00000"/>
  </joint>
  <joint name="head_pitch_joint" type="fixed">
    <limit lower="-1.04000" upper="0.79000" effort="1.67000" velocity="6.98000"/>
    <origin rpy="0.00000 0.00000 0.00000" xyz="0.00000 0.01895 0.01900"/>
    <parent link="head_yaw_link"/>
    <child link="head_pitch_link"/>
    <axis xyz="0.00000 1.00000 0.00000"/>
  </joint>
  <joint name="head_roll_joint" type="fixed">
    <limit lower="-0.79000" upper="0.79000" effort="1.67000" velocity="6.98000"/>
    <origin rpy="0.00000 0.00000 0.00000" xyz="-0.05040 -0.01900 0.01035"/>
    <parent link="head_pitch_link"/>
    <child link="head_roll_link"/>
    <axis xyz="1.00000 0.00000 0.00000"/>
  </joint>
  <joint name="left_shoulder_pitch_joint" type="fixed">
    <limit lower="-3.14000" upper="3.14000" effort="1.67000" velocity="6.98000"/>
    <origin rpy="0.00000 -0.00000 0.00000" xyz="-0.01731 0.09853 0.13050"/>
    <parent link="torso_yaw_link"/>
    <child link="left_shoulder_pitch_link"/>
    <axis xyz="0.00000 1.00000 0.00000"/>
  </joint>
  <joint name="left_shoulder_roll_joint" type="fixed">
    <limit lower="0.00000" upper="3.14000" effort="1.67000" velocity="6.98000"/>
    <origin rpy="0.00000 0.00000 0.00000" xyz="0.01895 0.02129 -0.00200"/>
    <parent link="left_shoulder_pitch_link"/>
    <child link="left_shoulder_roll_link"/>
    <axis xyz="1.00000 0.00000 0.00000"/>
  </joint>
  <joint name="left_shoulder_yaw_joint" type="fixed">
    <limit lower="-0.79000" upper="1.57000" effort="1.67000" velocity="6.98000"/>
    <origin rpy="-0.00000 -0.00000 -0.00000" xyz="-0.03227 0.00000 -0.04000"/>
    <parent link="left_shoulder_roll_link"/>
    <child link="left_shoulder_yaw_link"/>
    <axis xyz="0.00000 0.00000 1.00000"/>
  </joint>
  <joint name="left_elbow_pitch_joint" type="fixed">
    <limit lower="-0.79000" upper="1.57000" effort="1.67000" velocity="6.98000"/>
    <origin rpy="-0.00000 0.00000 0.00000" xyz="0.01425 -0.01941 -0.11783"/>
    <parent link="left_shoulder_yaw_link"/>
    <child link="left_elbow_pitch_link"/>
    <axis xyz="0.00000 1.00000 0.00000"/>
  </joint>
  <joint name="left_hand_joint" type="fixed">
    <limit lower="-3.14000" upper="3.14000" effort="0.00000" velocity="0.00000"/>
    <origin rpy="0.00000 -0.00000 -0.00000" xyz="0.12264 0.03079 -0.00449"/>
    <parent link="left_elbow_pitch_link"/>
    <child link="left_hand_link"/>
    <axis xyz="0.00000 0.00000 1.00000"/>
  </joint>
  <joint name="right_shoulder_pitch_joint" type="fixed">
    <limit lower="-3.14000" upper="3.14000" effort="1.67000" velocity="6.98000"/>
    <origin rpy="0.00000 -0.00000 0.00000" xyz="-0.01731 -0.09863 0.13050"/>
    <parent link="torso_yaw_link"/>
    <child link="right_shoulder_pitch_link"/>
    <axis xyz="0.00000 1.00000 0.00000"/>
  </joint>
  <joint name="right_shoulder_roll_joint" type="fixed">
    <limit lower="-3.14000" upper="0.00000" effort="1.67000" velocity="6.98000"/>
    <origin rpy="0.00000 0.00000 0.00000" xyz="0.01895 -0.02129 -0.00200"/>
    <parent link="right_shoulder_pitch_link"/>
    <child link="right_shoulder_roll_link"/>
    <axis xyz="1.00000 0.00000 0.00000"/>
  </joint>
  <joint name="right_shoulder_yaw_joint" type="fixed">
    <limit lower="-1.57000" upper="0.79000" effort="1.67000" velocity="6.98000"/>
    <origin rpy="0.00000 -0.00000 0.00000" xyz="-0.03227 -0.00000 -0.04000"/>
    <parent link="right_shoulder_roll_link"/>
    <child link="right_shoulder_yaw_link"/>
    <axis xyz="0.00000 0.00000 1.00000"/>
  </joint>
  <joint name="right_elbow_pitch_joint" type="fixed">
    <limit lower="-0.79000" upper="1.57000" effort="1.67000" velocity="6.98000"/>
    <origin rpy="0.00000 0.00000 -0.00000" xyz="0.01425 0.01941 -0.11783"/>
    <parent link="right_shoulder_yaw_link"/>
    <child link="right_elbow_pitch_link"/>
    <axis xyz="0.00000 1.00000 0.00000"/>
  </joint>
  <joint name="right_hand_joint" type="fixed">
    <limit lower="-3.14000" upper="3.14000" effort="0.00000" velocity="0.00000"/>
    <origin rpy="-0.00000 -0.00000 0.00000" xyz="0.12264 -0.03079 -0.00449"/>
    <parent link="right_elbow_pitch_link"/>
    <child link="right_hand_link"/>
    <axis xyz="0.00000 0.00000 1.00000"/>
  </joint>
  <link name="pelvis_link">
    <collision name="pelvis_link_collision">
      <origin rpy="1.57080 0.00000 1.57080" xyz="0.00000 0.00000 0.00000"/>
      <geometry>
        <mesh filename="../meshes/obj/pelvis_link_visual.obj" scale="1.00000 1.00000 1.00000"/>
      </geometry>
    </collision>
    <inertial>
      <inertia ixx="0.00028" ixy="-0.00001" ixz="-0.00006" iyy="0.00028" iyz="-0.00001" izz="0.00014"/>
      <origin rpy="0.00000 0.00000 0.00000" xyz="0.00139 0.00113 0.05161"/>
      <mass value="0.22800"/>
    </inertial>
    <visual name="pelvis_link_visual">
      <material name="ID10"/>
      <origin rpy="1.57080 0.00000 1.57080" xyz="-0.00000 0.00000 0.00000"/>
      <geometry>
        <mesh filename="../meshes/obj/pelvis_link_visual.obj" scale="1.00000 1.00000 1.00000"/>
      </geometry>
    </visual>
  </link>
  <link name="left_hip_roll_link">
    <collision name="left_hip_roll_link_collision">
      <origin rpy="1.57080 0.00000 1.57080" xyz="0.00000 0.00000 0.00000"/>
      <geometry>
        <mesh filename="../meshes/obj/left_hip_roll_link_visual.obj" scale="1.00000 1.00000 1.00000"/>
      </geometry>
    </collision>
    <inertial>
      <inertia ixx="0.00010" ixy="0.00001" ixz="0.00000" iyy="0.00007" iyz="-0.00001" izz="0.00014"/>
      <origin rpy="0.00000 0.00000 0.00000" xyz="-0.02887 0.04588 0.00742"/>
      <mass value="0.11100"/>
    </inertial>
    <visual name="left_hip_roll_link_visual">
      <material name="ID10"/>
      <origin rpy="1.57080 0.00000 1.57080" xyz="0.00000 -0.00000 0.00000"/>
      <geometry>
        <mesh filename="../meshes/obj/left_hip_roll_link_visual.obj" scale="1.00000 1.00000 1.00000"/>
      </geometry>
    </visual>
  </link>
  <link name="right_knee_link">
    <collision name="right_knee_link_collision">
      <origin rpy="1.57080 -0.00000 -1.57080" xyz="0.00000 0.00000 0.00000"/>
      <geometry>
        <mesh filename="../meshes/obj/right_knee_link_visual.obj" scale="1.00000 1.00000 1.00000"/>
      </geometry>
    </collision>
    <inertial>
      <inertia ixx="0.00062" ixy="0.00000" ixz="-0.00002" iyy="0.00061" iyz="0.00000" izz="0.00007"/>
      <origin rpy="0.00000 0.00000 0.00000" xyz="-0.00211 0.01894 -0.08760"/>
      <mass value="0.27900"/>
    </inertial>
    <visual name="right_knee_link_visual">
      <material name="ID10"/>
      <origin rpy="1.57080 0.00000 -1.57080" xyz="0.00000 0.00000 0.00000"/>
      <geometry>
        <mesh filename="../meshes/obj/right_knee_link_visual.obj" scale="1.00000 1.00000 1.00000"/>
      </geometry>
    </visual>
  </link>
  <link name="right_ankle_roll_link">
    <collision name="right_ankle_roll_link_collision">
      <origin rpy="1.57080 0.00000 -1.57080" xyz="0.00000 -0.00000 0.00000"/>
      <geometry>
        <mesh filename="../meshes/obj/right_ankle_roll_link_visual.obj" scale="1.00000 1.00000 1.00000"/>
      </geometry>
    </collision>
    <inertial>
      <inertia ixx="0.00001" ixy="-0.00000" ixz="-0.00000" iyy="0.00001" iyz="0.00000" izz="0.00001"/>
      <origin rpy="0.00000 0.00000 0.00000" xyz="-0.01332 -0.00004 -0.01821"/>
      <mass value="0.03300"/>
    </inertial>
    <visual name="right_ankle_roll_link_visual">
      <material name="ID10"/>
      <origin rpy="1.57080 -0.00000 -1.57080" xyz="0.00000 0.00000 0.00000"/>
      <geometry>
        <mesh filename="../meshes/obj/right_ankle_roll_link_visual.obj" scale="1.00000 1.00000 1.00000"/>
      </geometry>
    </visual>
  </link>
  <link name="right_ankle_pitch_link">
    <collision name="right_ankle_pitch_link_collision">
      <origin rpy="1.57080 -0.00000 -1.57080" xyz="-0.00000 0.00000 0.00000"/>
      <geometry>
        <mesh filename="../meshes/obj/right_ankle_pitch_link_visual.obj" scale="1.00000 1.00000 1.00000"/>
      </geometry>
    </collision>
    <inertial>
      <inertia ixx="0.00008" ixy="-0.00000" ixz="0.00004" iyy="0.00054" iyz="0.00000" izz="0.00055"/>
      <origin rpy="0.00000 0.00000 0.00000" xyz="0.03081 0.01927 -0.03166"/>
      <mass value="0.26000"/>
    </inertial>
    <visual name="right_ankle_pitch_link_visual">
      <material name="ID10"/>
      <origin rpy="1.57080 0.00000 -1.57080" xyz="-0.00000 0.00000 0.00000"/>
      <geometry>
        <mesh filename="../meshes/obj/right_ankle_pitch_link_visual.obj" scale="1.00000 1.00000 1.00000"/>
      </geometry>
    </visual>
  </link>
  <link name="torso_pitch_link">
    <collision name="torso_pitch_link_collision">
      <origin rpy="1.57080 0.00000 1.57080" xyz="0.00000 0.00000 0.00000"/>
      <geometry>
        <mesh filename="../meshes/obj/torso_pitch_link_visual.obj" scale="1.00000 1.00000 1.00000"/>
      </geometry>
    </collision>
    <inertial>
      <inertia ixx="0.00008" ixy="0.00000" ixz="0.00003" iyy="0.00015" iyz="0.00000" izz="0.00012"/>
      <origin rpy="0.00000 0.00000 0.00000" xyz="-0.02162 -0.02991 0.03377"/>
      <mass value="0.15300"/>
    </inertial>
    <visual name="torso_pitch_link_visual">
      <material name="ID10"/>
      <origin rpy="1.57080 0.00000 1.57080" xyz="0.00000 0.00000 0.00000"/>
      <geometry>
        <mesh filename="../meshes/obj/torso_pitch_link_visual.obj" scale="1.00000 1.00000 1.00000"/>
      </geometry>
    </visual>
  </link>
  <link name="torso_roll_link">
    <collision name="torso_roll_link_collision">
      <origin rpy="1.57080 0.00000 1.57080" xyz="-0.00000 -0.00000 0.00000"/>
      <geometry>
        <mesh filename="../meshes/obj/torso_roll_link_visual.obj" scale="1.00000 1.00000 1.00000"/>
      </geometry>
    </collision>
    <inertial>
      <inertia ixx="0.00004" ixy="0.00000" ixz="-0.00001" iyy="0.00011" iyz="0.00000" izz="0.00009"/>
      <origin rpy="0.00000 0.00000 0.00000" xyz="0.05020 -0.00000 0.03796"/>
      <mass value="0.05400"/>
    </inertial>
    <visual name="torso_roll_link_visual">
      <material name="ID10"/>
      <origin rpy="1.57080 0.00000 1.57080" xyz="0.00000 0.00000 0.00000"/>
      <geometry>
        <mesh filename="../meshes/obj/torso_roll_link_visual.obj" scale="1.00000 1.00000 1.00000"/>
      </geometry>
    </visual>
  </link>
  <link name="torso_yaw_link">
    <collision name="torso_yaw_link_collision">
      <origin rpy="1.57080 0.00000 1.57080" xyz="0.00000 -0.00000 0.00000"/>
      <geometry>
        <mesh filename="../meshes/obj/torso_yaw_link_visual.obj" scale="1.00000 1.00000 1.00000"/>
      </geometry>
    </collision>
    <inertial>
      <inertia ixx="0.00757" ixy="-0.00001" ixz="-0.00151" iyy="0.00860" iyz="0.00000" izz="0.01034"/>
      <origin rpy="0.00000 0.00000 0.00000" xyz="-0.02286 -0.00002 0.10185"/>
      <mass value="2.66900"/>
    </inertial>
    <visual name="torso_yaw_link_visual">
      <material name="ID10"/>
      <origin rpy="1.57080 0.00000 1.57080" xyz="0.00000 -0.00000 0.00000"/>
      <geometry>
        <mesh filename="../meshes/obj/torso_yaw_link_visual.obj" scale="1.00000 1.00000 1.00000"/>
      </geometry>
    </visual>
  </link>
  <link name="head_yaw_link">
    <collision name="head_yaw_link_collision">
      <origin rpy="1.57080 0.00000 1.57080" xyz="0.00000 0.00000 0.00000"/>
      <geometry>
        <mesh filename="../meshes/obj/head_yaw_link_visual.obj" scale="1.00000 1.00000 1.00000"/>
      </geometry>
    </collision>
    <inertial>
      <inertia ixx="0.00000" ixy="0.00000" ixz="-0.00000" iyy="0.00000" iyz="-0.00000" izz="0.00000"/>
      <origin rpy="0.00000 0.00000 0.00000" xyz="0.00000 -0.00011 0.00995"/>
      <mass value="0.00700"/>
    </inertial>
    <visual name="head_yaw_link_visual">
      <material name="ID10"/>
      <origin rpy="1.57080 0.00000 1.57080" xyz="0.00000 0.00000 0.00000"/>
      <geometry>
        <mesh filename="../meshes/obj/head_yaw_link_visual.obj" scale="1.00000 1.00000 1.00000"/>
      </geometry>
    </visual>
  </link>
  <link name="head_pitch_link">
    <collision name="head_pitch_link_collision">
      <origin rpy="1.57080 0.00000 1.57080" xyz="0.00000 0.00000 0.00000"/>
      <geometry>
        <mesh filename="../meshes/obj/head_pitch_link_visual.obj" scale="1.00000 1.00000 1.00000"/>
      </geometry>
    </collision>
    <inertial>
      <inertia ixx="0.00022" ixy="-0.00000" ixz="0.00005" iyy="0.00045" iyz="-0.00001" izz="0.00040"/>
      <origin rpy="0.00000 0.00000 0.00000" xyz="-0.01341 -0.01872 0.02093"/>
      <mass value="0.91300"/>
    </inertial>
    <visual name="head_pitch_link_visual">
      <material name="ID10"/>
      <origin rpy="1.57080 0.00000 1.57080" xyz="0.00000 0.00000 0.00000"/>
      <geometry>
        <mesh filename="../meshes/obj/head_pitch_link_visual.obj" scale="1.00000 1.00000 1.00000"/>
      </geometry>
    </visual>
  </link>
  <link name="head_roll_link">
    <collision name="head_roll_link_collision">
      <origin rpy="1.57080 0.00000 1.57080" xyz="0.00000 0.00000 0.00000"/>
      <geometry>
        <mesh filename="../meshes/obj/head_roll_link_visual.obj" scale="1.00000 1.00000 1.00000"/>
      </geometry>
    </collision>
    <inertial>
      <inertia ixx="0.00030" ixy="0.00001" ixz="0.00003" iyy="0.00027" iyz="-0.00001" izz="0.00028"/>
      <origin rpy="0.00000 0.00000 0.00000" xyz="0.04527 -0.00064 0.05106"/>
      <mass value="0.20600"/>
    </inertial>
    <visual name="head_roll_link_visual">
      <material name="ID10"/>
      <origin rpy="1.57080 0.00000 1.57080" xyz="0.00000 0.00000 0.00000"/>
      <geometry>
        <mesh filename="../meshes/obj/head_roll_link_visual.obj" scale="1.00000 1.00000 1.00000"/>
      </geometry>
    </visual>
  </link>
  <link name="left_shoulder_pitch_link">
    <collision name="left_shoulder_pitch_link_collision">
      <origin rpy="3.14159 -0.00000 1.57080" xyz="0.00000 0.00000 0.00000"/>
      <geometry>
        <mesh filename="../meshes/obj/left_shoulder_pitch_link_visual.obj" scale="1.00000 1.00000 1.00000"/>
      </geometry>
    </collision>
    <inertial>
      <inertia ixx="0.00000" ixy="-0.00000" ixz="0.00000" iyy="0.00000" iyz="-0.00000" izz="0.00000"/>
      <origin rpy="0.00000 0.00000 0.00000" xyz="0.00005 0.00922 -0.00183"/>
      <mass value="0.01200"/>
    </inertial>
    <visual name="left_shoulder_pitch_link_visual">
      <material name="ID10"/>
      <origin rpy="-3.14159 -0.00000 1.57080" xyz="0.00000 0.00000 0.00000"/>
      <geometry>
        <mesh filename="../meshes/obj/left_shoulder_pitch_link_visual.obj" scale="1.00000 1.00000 1.00000"/>
      </geometry>
    </visual>
  </link>
  <link name="left_hip_yaw_link">
    <collision name="left_hip_yaw_link_collision">
      <origin rpy="1.57080 0.00001 1.57080" xyz="0.00000 0.00000 0.00000"/>
      <geometry>
        <mesh filename="../meshes/obj/left_hip_yaw_link_visual.obj" scale="1.00000 1.00000 1.00000"/>
      </geometry>
    </collision>
    <inertial>
      <inertia ixx="0.00003" ixy="-0.00000" ixz="0.00000" iyy="0.00001" iyz="0.00000" izz="0.00002"/>
      <origin rpy="0.00000 0.00000 0.00000" xyz="-0.00450 -0.00222 -0.01543"/>
      <mass value="0.03200"/>
    </inertial>
    <visual name="left_hip_yaw_link_visual">
      <material name="ID10"/>
      <origin rpy="1.57080 0.00001 1.57080" xyz="0.00000 0.00000 0.00000"/>
      <geometry>
        <mesh filename="../meshes/obj/left_hip_yaw_link_visual.obj" scale="1.00000 1.00000 1.00000"/>
      </geometry>
    </visual>
  </link>
  <link name="left_shoulder_roll_link">
    <collision name="left_shoulder_roll_link_collision">
      <origin rpy="1.57080 1.57080 0.00000" xyz="0.00000 0.00000 0.00000"/>
      <geometry>
        <mesh filename="../meshes/obj/left_shoulder_roll_link_visual.obj" scale="1.00000 1.00000 1.00000"/>
      </geometry>
    </collision>
    <inertial>
      <inertia ixx="0.00013" ixy="0.00000" ixz="-0.00000" iyy="0.00007" iyz="0.00002" izz="0.00010"/>
      <origin rpy="0.00000 0.00000 0.00000" xyz="-0.02050 0.00000 -0.02149"/>
      <mass value="0.36800"/>
    </inertial>
    <visual name="left_shoulder_roll_link_visual">
      <material name="ID10"/>
      <origin rpy="1.57080 1.57080 0.00000" xyz="0.00000 0.00000 0.00000"/>
      <geometry>
        <mesh filename="../meshes/obj/left_shoulder_roll_link_visual.obj" scale="1.00000 1.00000 1.00000"/>
      </geometry>
    </visual>
  </link>
  <link name="left_shoulder_yaw_link">
    <collision name="left_shoulder_yaw_link_collision">
      <origin rpy="-1.57080 0.00000 -1.57080" xyz="0.00000 0.00000 -0.00000"/>
      <geometry>
        <mesh filename="../meshes/obj/left_shoulder_yaw_link_visual.obj" scale="1.00000 1.00000 1.00000"/>
      </geometry>
    </collision>
    <inertial>
      <inertia ixx="0.00052" ixy="0.00000" ixz="0.00000" iyy="0.00012" iyz="-0.00000" izz="0.00050"/>
      <origin rpy="0.00000 0.00000 0.00000" xyz="0.01432 0.00005 -0.05788"/>
      <mass value="0.39400"/>
    </inertial>
    <visual name="left_shoulder_yaw_link_visual">
      <material name="ID10"/>
      <origin rpy="-1.57080 -0.00000 -1.57080" xyz="0.00000 0.00000 -0.00000"/>
      <geometry>
        <mesh filename="../meshes/obj/left_shoulder_yaw_link_visual.obj" scale="1.00000 1.00000 1.00000"/>
      </geometry>
    </visual>
  </link>
  <link name="left_elbow_pitch_link">
    <collision name="left_elbow_pitch_link_collision">
      <origin rpy="0.00000 -0.00000 -1.57080" xyz="-0.00000 0.00000 -0.00000"/>
      <geometry>
        <mesh filename="../meshes/obj/left_elbow_pitch_link_visual.obj" scale="1.00000 1.00000 1.00000"/>
      </geometry>
    </collision>
    <inertial>
      <inertia ixx="0.00029" ixy="0.00003" ixz="0.00000" iyy="0.00005" iyz="-0.00002" izz="0.00031"/>
      <origin rpy="0.00000 0.00000 0.00000" xyz="0.05050 0.02373 -0.00880"/>
      <mass value="0.17000"/>
    </inertial>
    <visual name="left_elbow_pitch_link_visual">
      <material name="ID10"/>
      <origin rpy="0.00000 -0.00000 -1.57080" xyz="-0.00000 0.00000 -0.00000"/>
      <geometry>
        <mesh filename="../meshes/obj/left_elbow_pitch_link_visual.obj" scale="1.00000 1.00000 1.00000"/>
      </geometry>
    </visual>
  </link>
  <link name="left_hand_link">
    <visual name="left_gloves_link_visual">
      <material name="ID32"/>
      <origin rpy="1.57080 0.00000 -0.00000" xyz="0.00000 -0.00000 -0.00000"/>
      <geometry>
        <mesh filename="../meshes/obj/ID26.obj" scale="1.00000 1.00000 1.00000"/>
      </geometry>
    </visual>
    <visual name="left_hand_link_visual">
      <material name="ID10"/>
      <origin rpy="1.57080 0.00000 -0.00000" xyz="0.00000 -0.00000 -0.00000"/>
      <geometry>
        <mesh filename="../meshes/obj/ID535.obj" scale="1.00000 1.00000 1.00000"/>
      </geometry>
    </visual>
  </link>
  <link name="right_shoulder_pitch_link">
    <collision name="right_shoulder_pitch_link_collision">
      <origin rpy="3.14159 -0.00000 1.57080" xyz="0.00000 -0.00000 -0.00000"/>
      <geometry>
        <mesh filename="../meshes/obj/right_shoulder_pitch_link_visual.obj" scale="1.00000 1.00000 1.00000"/>
      </geometry>
    </collision>
    <inertial>
      <inertia ixx="0.00000" ixy="0.00000" ixz="0.00000" iyy="0.00000" iyz="0.00000" izz="0.00000"/>
      <origin rpy="0.00000 0.00000 0.00000" xyz="0.00005 -0.00922 -0.00183"/>
      <mass value="0.01200"/>
    </inertial>
    <visual name="right_shoulder_pitch_link_visual">
      <material name="ID10"/>
      <origin rpy="-3.14159 -0.00000 1.57080" xyz="0.00000 -0.00000 -0.00000"/>
      <geometry>
        <mesh filename="../meshes/obj/right_shoulder_pitch_link_visual.obj" scale="1.00000 1.00000 1.00000"/>
      </geometry>
    </visual>
  </link>
  <link name="right_shoulder_roll_link">
    <collision name="right_shoulder_roll_link_collision">
      <origin rpy="-1.57080 -1.57080 0.00000" xyz="0.00000 0.00000 -0.00000"/>
      <geometry>
        <mesh filename="../meshes/obj/right_shoulder_roll_link_visual.obj" scale="1.00000 1.00000 1.00000"/>
      </geometry>
    </collision>
    <inertial>
      <inertia ixx="0.00013" ixy="-0.00000" ixz="-0.00000" iyy="0.00007" iyz="-0.00002" izz="0.00010"/>
      <origin rpy="0.00000 0.00000 0.00000" xyz="-0.02050 0.00000 -0.02149"/>
      <mass value="0.36800"/>
    </inertial>
    <visual name="right_shoulder_roll_link_visual">
      <material name="ID10"/>
      <origin rpy="-1.57080 -1.57080 0.00000" xyz="0.00000 0.00000 -0.00000"/>
      <geometry>
        <mesh filename="../meshes/obj/right_shoulder_roll_link_visual.obj" scale="1.00000 1.00000 1.00000"/>
      </geometry>
    </visual>
  </link>
  <link name="right_shoulder_yaw_link">
    <collision name="right_shoulder_yaw_link_collision">
      <origin rpy="1.57080 -0.00000 1.57080" xyz="0.00000 0.00000 -0.00000"/>
      <geometry>
        <mesh filename="../meshes/obj/right_shoulder_yaw_link_visual.obj" scale="1.00000 1.00000 1.00000"/>
      </geometry>
    </collision>
    <inertial>
      <inertia ixx="0.00052" ixy="-0.00000" ixz="0.00000" iyy="0.00012" iyz="0.00000" izz="0.00051"/>
      <origin rpy="0.00000 0.00000 0.00000" xyz="0.01432 -0.00005 -0.05788"/>
      <mass value="0.39400"/>
    </inertial>
    <visual name="right_shoulder_yaw_link_visual">
      <material name="ID10"/>
      <origin rpy="1.57080 -0.00000 1.57080" xyz="0.00000 0.00000 -0.00000"/>
      <geometry>
        <mesh filename="../meshes/obj/right_shoulder_yaw_link_visual.obj" scale="1.00000 1.00000 1.00000"/>
      </geometry>
    </visual>
  </link>
  <link name="right_elbow_pitch_link">
    <collision name="right_elbow_pitch_link_collision">
      <origin rpy="-0.00000 -0.00000 1.57080" xyz="-0.00000 -0.00000 0.00000"/>
      <geometry>
        <mesh filename="../meshes/obj/right_elbow_pitch_link_visual.obj" scale="1.00000 1.00000 1.00000"/>
      </geometry>
    </collision>
    <inertial>
      <inertia ixx="0.00029" ixy="-0.00003" ixz="0.00000" iyy="0.00005" iyz="0.00002" izz="0.00030"/>
      <origin rpy="0.00000 0.00000 0.00000" xyz="0.05050 -0.02373 -0.00880"/>
      <mass value="0.17000"/>
    </inertial>
    <visual name="right_elbow_pitch_link_visual">
      <material name="ID10"/>
      <origin rpy="-0.00000 -0.00000 1.57080" xyz="-0.00000 0.00000 0.00000"/>
      <geometry>
        <mesh filename="../meshes/obj/right_elbow_pitch_link_visual.obj" scale="1.00000 1.00000 1.00000"/>
      </geometry>
    </visual>
  </link>
  <link name="right_hand_link">
    <visual name="right_gloves_link_visual">
      <material name="ID32"/>
      <origin rpy="-1.57080 0.00000 0.00000" xyz="0.00000 -0.00000 0.00000"/>
      <geometry>
        <mesh filename="../meshes/obj/ID26.obj" scale="1.00000 1.00000 1.00000"/>
      </geometry>
    </visual>
    <visual name="right_hand_link_visual">
      <material name="ID10"/>
      <origin rpy="1.57080 -0.00000 -3.14159" xyz="0.00000 -0.00000 0.00000"/>
      <geometry>
        <mesh filename="../meshes/obj/ID516.obj" scale="1.00000 1.00000 1.00000"/>
      </geometry>
    </visual>
  </link>
  <link name="left_hip_pitch_link">
    <collision name="left_hip_pitch_link_collision">
      <origin rpy="1.57080 -0.00001 -1.57080" xyz="0.00000 0.00000 -0.00000"/>
      <geometry>
        <mesh filename="../meshes/obj/left_hip_pitch_link_visual.obj" scale="1.00000 1.00000 1.00000"/>
      </geometry>
    </collision>
    <inertial>
      <inertia ixx="0.00084" ixy="0.00000" ixz="0.00002" iyy="0.00081" iyz="-0.00001" izz="0.00006"/>
      <origin rpy="0.00000 0.00000 0.00000" xyz="0.00095 -0.02965 -0.08431"/>
      <mass value="0.21600"/>
    </inertial>
    <visual name="left_hip_pitch_link_visual">
      <material name="ID10"/>
      <origin rpy="1.57080 -0.00001 -1.57080" xyz="0.00000 0.00000 0.00000"/>
      <geometry>
        <mesh filename="../meshes/obj/left_hip_pitch_link_visual.obj" scale="1.00000 1.00000 1.00000"/>
      </geometry>
    </visual>
  </link>
  <link name="left_knee_link">
    <collision name="left_knee_link_collision">
      <origin rpy="1.57080 -0.00001 -1.57080" xyz="0.00000 -0.00000 0.00000"/>
      <geometry>
        <mesh filename="../meshes/obj/left_knee_link_visual.obj" scale="1.00000 1.00000 1.00000"/>
      </geometry>
    </collision>
    <inertial>
      <inertia ixx="0.00059" ixy="-0.00000" ixz="-0.00002" iyy="0.00059" iyz="-0.00000" izz="0.00007"/>
      <origin rpy="0.00000 0.00000 0.00000" xyz="-0.00216 -0.01894 -0.08946"/>
      <mass value="0.27900"/>
    </inertial>
    <visual name="left_knee_link_visual">
      <material name="ID10"/>
      <origin rpy="1.57080 -0.00001 -1.57080" xyz="0.00000 0.00000 0.00000"/>
      <geometry>
        <mesh filename="../meshes/obj/left_knee_link_visual.obj" scale="1.00000 1.00000 1.00000"/>
      </geometry>
    </visual>
  </link>
  <link name="left_ankle_roll_link">
    <collision name="left_ankle_roll_link_collision">
      <origin rpy="1.57080 0.00001 1.57080" xyz="0.00000 0.00000 0.00000"/>
      <geometry>
        <mesh filename="../meshes/obj/left_ankle_roll_link_visual.001.obj" scale="1.00000 1.00000 1.00000"/>
      </geometry>
    </collision>
    <inertial>
      <inertia ixx="0.00001" ixy="0.00000" ixz="-0.00000" iyy="0.00001" iyz="-0.00000" izz="0.00001"/>
      <origin rpy="0.00000 0.00000 0.00000" xyz="-0.01358 0.00002 -0.01832"/>
      <mass value="0.03300"/>
    </inertial>
    <visual name="left_ankle_roll_link_visual">
      <material name="ID10"/>
      <origin rpy="1.57080 0.00001 1.57080" xyz="0.00000 0.00000 0.00000"/>
      <geometry>
        <mesh filename="../meshes/obj/left_ankle_roll_link_visual.001.obj" scale="1.00000 1.00000 1.00000"/>
      </geometry>
    </visual>
  </link>
  <link name="left_ankle_pitch_link">
    <collision name="left_ankle_pitch_link_collision">
      <origin rpy="1.57080 0.00001 1.57080" xyz="-0.00000 0.00000 0.00000"/>
      <geometry>
        <mesh filename="../meshes/obj/left_ankle_pitch_link_visual.obj" scale="1.00000 1.00000 1.00000"/>
      </geometry>
    </collision>
    <inertial>
      <inertia ixx="0.00008" ixy="-0.00001" ixz="0.00004" iyy="0.00054" iyz="0.00000" izz="0.00055"/>
      <origin rpy="0.00000 0.00000 0.00000" xyz="0.03078 -0.01922 -0.03167"/>
      <mass value="0.26000"/>
    </inertial>
    <visual name="left_ankle_pitch_link_visual">
      <material name="ID10"/>
      <origin rpy="1.57080 0.00001 1.57080" xyz="-0.00000 0.00000 0.00000"/>
      <geometry>
        <mesh filename="../meshes/obj/left_ankle_pitch_link_visual.obj" scale="1.00000 1.00000 1.00000"/>
      </geometry>
    </visual>
  </link>
  <link name="right_hip_roll_link">
    <collision name="right_hip_roll_link_collision">
      <origin rpy="1.57080 -0.34907 1.57080" xyz="0.00000 -0.00000 0.00000"/>
      <geometry>
        <mesh filename="../meshes/obj/right_hip_roll_link_visual.obj" scale="1.00000 1.00000 1.00000"/>
      </geometry>
    </collision>
    <inertial>
      <inertia ixx="0.00009" ixy="-0.00001" ixz="0.00000" iyy="0.00006" iyz="0.00001" izz="0.00012"/>
      <origin rpy="0.00000 0.00000 0.00000" xyz="-0.02882 -0.04587 0.00739"/>
      <mass value="0.11100"/>
    </inertial>
    <visual name="right_hip_roll_link_visual">
      <material name="ID10"/>
      <origin rpy="1.57080 -0.34907 1.57080" xyz="0.00000 0.00000 0.00000"/>
      <geometry>
        <mesh filename="../meshes/obj/right_hip_roll_link_visual.obj" scale="1.00000 1.00000 1.00000"/>
      </geometry>
    </visual>
  </link>
  <link name="right_hip_yaw_link">
    <collision name="right_hip_yaw_link_collision">
      <origin rpy="1.57080 0.00000 1.57080" xyz="0.00000 0.00000 0.00000"/>
      <geometry>
        <mesh filename="../meshes/obj/right_hip_yaw_link_visual.obj" scale="1.00000 1.00000 1.00000"/>
      </geometry>
    </collision>
    <inertial>
      <inertia ixx="0.00003" ixy="0.00000" ixz="0.00000" iyy="0.00001" iyz="-0.00000" izz="0.00002"/>
      <origin rpy="0.00000 0.00000 0.00000" xyz="-0.00450 0.00222 -0.01543"/>
      <mass value="0.03200"/>
    </inertial>
    <visual name="right_hip_yaw_link_visual">
      <material name="ID10"/>
      <origin rpy="1.57080 0.00000 1.57080" xyz="0.00000 0.00000 0.00000"/>
      <geometry>
        <mesh filename="../meshes/obj/right_hip_yaw_link_visual.obj" scale="1.00000 1.00000 1.00000"/>
      </geometry>
    </visual>
  </link>
  <link name="right_hip_pitch_link">
    <collision name="right_hip_pitch_link_collision">
      <origin rpy="1.57080 0.00000 1.57080" xyz="-0.00000 -0.00000 -0.00000"/>
      <geometry>
        <mesh filename="../meshes/obj/right_hip_pitch_link_visual.obj" scale="1.00000 1.00000 1.00000"/>
      </geometry>
    </collision>
    <inertial>
      <inertia ixx="0.00086" ixy="-0.00000" ixz="0.00002" iyy="0.00083" iyz="0.00001" izz="0.00006"/>
      <origin rpy="0.00000 0.00000 0.00000" xyz="0.00132 0.02953 -0.08065"/>
      <mass value="0.21600"/>
    </inertial>
    <visual name="right_hip_pitch_link_visual">
      <material name="ID10"/>
      <origin rpy="1.57080 0.00000 1.57080" xyz="0.00000 0.00000 0.00000"/>
      <geometry>
        <mesh filename="../meshes/obj/right_hip_pitch_link_visual.obj" scale="1.00000 1.00000 1.00000"/>
      </geometry>
    </visual>
  </link>
  <material name="ID10">
    <color rgba="0.44706 0.17647 0.21176 1.00000"/>
  </material>
  <material name="ID32">
    <color rgba="0.09020 0.09020 0.09020 1.00000"/>
  </material>
</robot>